ERROR 2019-04-28 04:28:53,951 django.request Internal Server Error: /api/v1/restaurant/
Traceback (most recent call last):
  File "/Users/300047924/workspaces/hashedin/Project3/venv/lib/python3.6/site-packages/django/db/backends/utils.py", line 65, in execute
    return self.cursor.execute(sql, params)
  File "/Users/300047924/workspaces/hashedin/Project3/venv/lib/python3.6/site-packages/django/db/backends/sqlite3/base.py", line 328, in execute
    return Database.Cursor.execute(self, query, params)
sqlite3.OperationalError: no such column: foodordering_restaurant.description

The above exception was the direct cause of the following exception:

Traceback (most recent call last):
  File "/Users/300047924/workspaces/hashedin/Project3/venv/lib/python3.6/site-packages/django/core/handlers/exception.py", line 41, in inner
    response = get_response(request)
  File "/Users/300047924/workspaces/hashedin/Project3/venv/lib/python3.6/site-packages/django/core/handlers/base.py", line 187, in _get_response
    response = self.process_exception_by_middleware(e, request)
  File "/Users/300047924/workspaces/hashedin/Project3/venv/lib/python3.6/site-packages/django/core/handlers/base.py", line 185, in _get_response
    response = wrapped_callback(request, *callback_args, **callback_kwargs)
  File "/Users/300047924/workspaces/hashedin/Project3/venv/lib/python3.6/site-packages/django/views/decorators/csrf.py", line 58, in wrapped_view
    return view_func(*args, **kwargs)
  File "/Users/300047924/workspaces/hashedin/Project3/venv/lib/python3.6/site-packages/django/views/generic/base.py", line 68, in view
    return self.dispatch(request, *args, **kwargs)
  File "/Users/300047924/workspaces/hashedin/Project3/venv/lib/python3.6/site-packages/rest_framework/views.py", line 489, in dispatch
    response = self.handle_exception(exc)
  File "/Users/300047924/workspaces/hashedin/Project3/venv/lib/python3.6/site-packages/rest_framework/views.py", line 449, in handle_exception
    self.raise_uncaught_exception(exc)
  File "/Users/300047924/workspaces/hashedin/Project3/venv/lib/python3.6/site-packages/rest_framework/views.py", line 486, in dispatch
    response = handler(request, *args, **kwargs)
  File "/Users/300047924/workspaces/hashedin/Project3/foodordering/views.py", line 16, in get
    return Response(serializer.data)
  File "/Users/300047924/workspaces/hashedin/Project3/venv/lib/python3.6/site-packages/rest_framework/serializers.py", line 739, in data
    ret = super(ListSerializer, self).data
  File "/Users/300047924/workspaces/hashedin/Project3/venv/lib/python3.6/site-packages/rest_framework/serializers.py", line 263, in data
    self._data = self.to_representation(self.instance)
  File "/Users/300047924/workspaces/hashedin/Project3/venv/lib/python3.6/site-packages/rest_framework/serializers.py", line 657, in to_representation
    self.child.to_representation(item) for item in iterable
  File "/Users/300047924/workspaces/hashedin/Project3/venv/lib/python3.6/site-packages/django/db/models/query.py", line 250, in __iter__
    self._fetch_all()
  File "/Users/300047924/workspaces/hashedin/Project3/venv/lib/python3.6/site-packages/django/db/models/query.py", line 1103, in _fetch_all
    self._result_cache = list(self._iterable_class(self))
  File "/Users/300047924/workspaces/hashedin/Project3/venv/lib/python3.6/site-packages/django/db/models/query.py", line 53, in __iter__
    results = compiler.execute_sql(chunked_fetch=self.chunked_fetch)
  File "/Users/300047924/workspaces/hashedin/Project3/venv/lib/python3.6/site-packages/django/db/models/sql/compiler.py", line 886, in execute_sql
    raise original_exception
  File "/Users/300047924/workspaces/hashedin/Project3/venv/lib/python3.6/site-packages/django/db/models/sql/compiler.py", line 876, in execute_sql
    cursor.execute(sql, params)
  File "/Users/300047924/workspaces/hashedin/Project3/venv/lib/python3.6/site-packages/django/db/backends/utils.py", line 80, in execute
    return super(CursorDebugWrapper, self).execute(sql, params)
  File "/Users/300047924/workspaces/hashedin/Project3/venv/lib/python3.6/site-packages/django/db/backends/utils.py", line 65, in execute
    return self.cursor.execute(sql, params)
  File "/Users/300047924/workspaces/hashedin/Project3/venv/lib/python3.6/site-packages/django/db/utils.py", line 94, in __exit__
    six.reraise(dj_exc_type, dj_exc_value, traceback)
  File "/Users/300047924/workspaces/hashedin/Project3/venv/lib/python3.6/site-packages/django/utils/six.py", line 685, in reraise
    raise value.with_traceback(tb)
  File "/Users/300047924/workspaces/hashedin/Project3/venv/lib/python3.6/site-packages/django/db/backends/utils.py", line 65, in execute
    return self.cursor.execute(sql, params)
  File "/Users/300047924/workspaces/hashedin/Project3/venv/lib/python3.6/site-packages/django/db/backends/sqlite3/base.py", line 328, in execute
    return Database.Cursor.execute(self, query, params)
django.db.utils.OperationalError: no such column: foodordering_restaurant.description
ERROR 2019-04-28 04:28:53,992 django.server "GET /api/v1/restaurant/ HTTP/1.1" 500 20531
ERROR 2019-04-28 06:40:17,281 django.request Internal Server Error: /api/v1/orders/
Traceback (most recent call last):
  File "/Users/300047924/workspaces/hashedin/Project3/venv/lib/python3.6/site-packages/django/core/handlers/exception.py", line 41, in inner
    response = get_response(request)
  File "/Users/300047924/workspaces/hashedin/Project3/venv/lib/python3.6/site-packages/django/core/handlers/base.py", line 187, in _get_response
    response = self.process_exception_by_middleware(e, request)
  File "/Users/300047924/workspaces/hashedin/Project3/venv/lib/python3.6/site-packages/django/core/handlers/base.py", line 185, in _get_response
    response = wrapped_callback(request, *callback_args, **callback_kwargs)
  File "/Users/300047924/workspaces/hashedin/Project3/venv/lib/python3.6/site-packages/django/views/decorators/csrf.py", line 58, in wrapped_view
    return view_func(*args, **kwargs)
  File "/Users/300047924/workspaces/hashedin/Project3/venv/lib/python3.6/site-packages/django/views/generic/base.py", line 68, in view
    return self.dispatch(request, *args, **kwargs)
  File "/Users/300047924/workspaces/hashedin/Project3/venv/lib/python3.6/site-packages/rest_framework/views.py", line 489, in dispatch
    response = self.handle_exception(exc)
  File "/Users/300047924/workspaces/hashedin/Project3/venv/lib/python3.6/site-packages/rest_framework/views.py", line 449, in handle_exception
    self.raise_uncaught_exception(exc)
  File "/Users/300047924/workspaces/hashedin/Project3/venv/lib/python3.6/site-packages/rest_framework/views.py", line 486, in dispatch
    response = handler(request, *args, **kwargs)
  File "/Users/300047924/workspaces/hashedin/Project3/foodordering/views.py", line 40, in get
    return Response(serializer.data)
  File "/Users/300047924/workspaces/hashedin/Project3/venv/lib/python3.6/site-packages/rest_framework/serializers.py", line 739, in data
    ret = super(ListSerializer, self).data
  File "/Users/300047924/workspaces/hashedin/Project3/venv/lib/python3.6/site-packages/rest_framework/serializers.py", line 263, in data
    self._data = self.to_representation(self.instance)
  File "/Users/300047924/workspaces/hashedin/Project3/venv/lib/python3.6/site-packages/rest_framework/serializers.py", line 657, in to_representation
    self.child.to_representation(item) for item in iterable
  File "/Users/300047924/workspaces/hashedin/Project3/venv/lib/python3.6/site-packages/rest_framework/serializers.py", line 657, in <listcomp>
    self.child.to_representation(item) for item in iterable
  File "/Users/300047924/workspaces/hashedin/Project3/venv/lib/python3.6/site-packages/rest_framework/serializers.py", line 484, in to_representation
    fields = self._readable_fields
  File "/Users/300047924/workspaces/hashedin/Project3/venv/lib/python3.6/site-packages/django/utils/functional.py", line 35, in __get__
    res = instance.__dict__[self.name] = self.func(instance)
  File "/Users/300047924/workspaces/hashedin/Project3/venv/lib/python3.6/site-packages/rest_framework/serializers.py", line 378, in _readable_fields
    field for field in self.fields.values()
  File "/Users/300047924/workspaces/hashedin/Project3/venv/lib/python3.6/site-packages/rest_framework/serializers.py", line 364, in fields
    for key, value in self.get_fields().items():
  File "/Users/300047924/workspaces/hashedin/Project3/venv/lib/python3.6/site-packages/rest_framework/serializers.py", line 994, in get_fields
    field_names = self.get_field_names(declared_fields, info)
  File "/Users/300047924/workspaces/hashedin/Project3/venv/lib/python3.6/site-packages/rest_framework/serializers.py", line 1093, in get_field_names
    serializer_class=self.__class__.__name__
AssertionError: The field 'item' was declared on serializer OrderSerializer, but has not been included in the 'fields' option.
ERROR 2019-04-28 06:40:17,311 django.server "GET /api/v1/orders/ HTTP/1.1" 500 19731
ERROR 2019-04-28 06:54:31,011 django.request Internal Server Error: /api/v1/register/
Traceback (most recent call last):
  File "/Users/300047924/workspaces/hashedin/Project3/venv/lib/python3.6/site-packages/django/core/handlers/exception.py", line 41, in inner
    response = get_response(request)
  File "/Users/300047924/workspaces/hashedin/Project3/venv/lib/python3.6/site-packages/django/core/handlers/base.py", line 187, in _get_response
    response = self.process_exception_by_middleware(e, request)
  File "/Users/300047924/workspaces/hashedin/Project3/venv/lib/python3.6/site-packages/django/core/handlers/base.py", line 185, in _get_response
    response = wrapped_callback(request, *callback_args, **callback_kwargs)
  File "/Users/300047924/workspaces/hashedin/Project3/venv/lib/python3.6/site-packages/django/views/decorators/csrf.py", line 58, in wrapped_view
    return view_func(*args, **kwargs)
  File "/Users/300047924/workspaces/hashedin/Project3/venv/lib/python3.6/site-packages/django/views/generic/base.py", line 68, in view
    return self.dispatch(request, *args, **kwargs)
  File "/Users/300047924/workspaces/hashedin/Project3/venv/lib/python3.6/site-packages/rest_framework/views.py", line 489, in dispatch
    response = self.handle_exception(exc)
  File "/Users/300047924/workspaces/hashedin/Project3/venv/lib/python3.6/site-packages/rest_framework/views.py", line 449, in handle_exception
    self.raise_uncaught_exception(exc)
  File "/Users/300047924/workspaces/hashedin/Project3/venv/lib/python3.6/site-packages/rest_framework/views.py", line 486, in dispatch
    response = handler(request, *args, **kwargs)
  File "/Users/300047924/workspaces/hashedin/Project3/foodordering/views.py", line 68, in post
    serialized = UserSerializer(data=request.DATA)
  File "/Users/300047924/workspaces/hashedin/Project3/venv/lib/python3.6/site-packages/rest_framework/request.py", line 378, in __getattribute__
    return super(Request, self).__getattribute__(attr)
  File "/Users/300047924/workspaces/hashedin/Project3/venv/lib/python3.6/site-packages/rest_framework/request.py", line 389, in DATA
    '`request.DATA` has been deprecated in favor of `request.data` '
NotImplementedError: `request.DATA` has been deprecated in favor of `request.data` since version 3.0, and has been fully removed as of version 3.2.
ERROR 2019-04-28 06:54:31,032 django.server "POST /api/v1/register/ HTTP/1.1" 500 18229
ERROR 2019-04-28 06:54:45,326 django.request Internal Server Error: /api/v1/register/
Traceback (most recent call last):
  File "/Users/300047924/workspaces/hashedin/Project3/venv/lib/python3.6/site-packages/django/core/handlers/exception.py", line 41, in inner
    response = get_response(request)
  File "/Users/300047924/workspaces/hashedin/Project3/venv/lib/python3.6/site-packages/django/core/handlers/base.py", line 187, in _get_response
    response = self.process_exception_by_middleware(e, request)
  File "/Users/300047924/workspaces/hashedin/Project3/venv/lib/python3.6/site-packages/django/core/handlers/base.py", line 185, in _get_response
    response = wrapped_callback(request, *callback_args, **callback_kwargs)
  File "/Users/300047924/workspaces/hashedin/Project3/venv/lib/python3.6/site-packages/django/views/decorators/csrf.py", line 58, in wrapped_view
    return view_func(*args, **kwargs)
  File "/Users/300047924/workspaces/hashedin/Project3/venv/lib/python3.6/site-packages/django/views/generic/base.py", line 68, in view
    return self.dispatch(request, *args, **kwargs)
  File "/Users/300047924/workspaces/hashedin/Project3/venv/lib/python3.6/site-packages/rest_framework/views.py", line 489, in dispatch
    response = self.handle_exception(exc)
  File "/Users/300047924/workspaces/hashedin/Project3/venv/lib/python3.6/site-packages/rest_framework/views.py", line 449, in handle_exception
    self.raise_uncaught_exception(exc)
  File "/Users/300047924/workspaces/hashedin/Project3/venv/lib/python3.6/site-packages/rest_framework/views.py", line 486, in dispatch
    response = handler(request, *args, **kwargs)
  File "/Users/300047924/workspaces/hashedin/Project3/foodordering/views.py", line 71, in post
    serialized.init_data['email'],
AttributeError: 'UserSerializer' object has no attribute 'init_data'
ERROR 2019-04-28 06:54:45,345 django.server "POST /api/v1/register/ HTTP/1.1" 500 17655
ERROR 2019-04-28 06:56:13,609 django.request Internal Server Error: /api/v1/register/
Traceback (most recent call last):
  File "/Users/300047924/workspaces/hashedin/Project3/venv/lib/python3.6/site-packages/django/core/handlers/exception.py", line 41, in inner
    response = get_response(request)
  File "/Users/300047924/workspaces/hashedin/Project3/venv/lib/python3.6/site-packages/django/core/handlers/base.py", line 187, in _get_response
    response = self.process_exception_by_middleware(e, request)
  File "/Users/300047924/workspaces/hashedin/Project3/venv/lib/python3.6/site-packages/django/core/handlers/base.py", line 185, in _get_response
    response = wrapped_callback(request, *callback_args, **callback_kwargs)
  File "/Users/300047924/workspaces/hashedin/Project3/venv/lib/python3.6/site-packages/django/views/decorators/csrf.py", line 58, in wrapped_view
    return view_func(*args, **kwargs)
  File "/Users/300047924/workspaces/hashedin/Project3/venv/lib/python3.6/site-packages/django/views/generic/base.py", line 68, in view
    return self.dispatch(request, *args, **kwargs)
  File "/Users/300047924/workspaces/hashedin/Project3/venv/lib/python3.6/site-packages/rest_framework/views.py", line 489, in dispatch
    response = self.handle_exception(exc)
  File "/Users/300047924/workspaces/hashedin/Project3/venv/lib/python3.6/site-packages/rest_framework/views.py", line 449, in handle_exception
    self.raise_uncaught_exception(exc)
  File "/Users/300047924/workspaces/hashedin/Project3/venv/lib/python3.6/site-packages/rest_framework/views.py", line 486, in dispatch
    response = handler(request, *args, **kwargs)
  File "/Users/300047924/workspaces/hashedin/Project3/foodordering/views.py", line 70, in post
    User.objects.create_user(serialized.data
  File "/Users/300047924/workspaces/hashedin/Project3/venv/lib/python3.6/site-packages/django/contrib/auth/models.py", line 159, in create_user
    return self._create_user(username, email, password, **extra_fields)
  File "/Users/300047924/workspaces/hashedin/Project3/venv/lib/python3.6/site-packages/django/contrib/auth/models.py", line 148, in _create_user
    raise ValueError('The given username must be set')
ValueError: The given username must be set
ERROR 2019-04-28 06:56:13,630 django.server "POST /api/v1/register/ HTTP/1.1" 500 18027
ERROR 2019-04-28 06:56:15,246 django.request Internal Server Error: /api/v1/register/
Traceback (most recent call last):
  File "/Users/300047924/workspaces/hashedin/Project3/venv/lib/python3.6/site-packages/django/core/handlers/exception.py", line 41, in inner
    response = get_response(request)
  File "/Users/300047924/workspaces/hashedin/Project3/venv/lib/python3.6/site-packages/django/core/handlers/base.py", line 187, in _get_response
    response = self.process_exception_by_middleware(e, request)
  File "/Users/300047924/workspaces/hashedin/Project3/venv/lib/python3.6/site-packages/django/core/handlers/base.py", line 185, in _get_response
    response = wrapped_callback(request, *callback_args, **callback_kwargs)
  File "/Users/300047924/workspaces/hashedin/Project3/venv/lib/python3.6/site-packages/django/views/decorators/csrf.py", line 58, in wrapped_view
    return view_func(*args, **kwargs)
  File "/Users/300047924/workspaces/hashedin/Project3/venv/lib/python3.6/site-packages/django/views/generic/base.py", line 68, in view
    return self.dispatch(request, *args, **kwargs)
  File "/Users/300047924/workspaces/hashedin/Project3/venv/lib/python3.6/site-packages/rest_framework/views.py", line 489, in dispatch
    response = self.handle_exception(exc)
  File "/Users/300047924/workspaces/hashedin/Project3/venv/lib/python3.6/site-packages/rest_framework/views.py", line 449, in handle_exception
    self.raise_uncaught_exception(exc)
  File "/Users/300047924/workspaces/hashedin/Project3/venv/lib/python3.6/site-packages/rest_framework/views.py", line 486, in dispatch
    response = handler(request, *args, **kwargs)
  File "/Users/300047924/workspaces/hashedin/Project3/foodordering/views.py", line 70, in post
    User.objects.create_user(serialized.data
  File "/Users/300047924/workspaces/hashedin/Project3/venv/lib/python3.6/site-packages/django/contrib/auth/models.py", line 159, in create_user
    return self._create_user(username, email, password, **extra_fields)
  File "/Users/300047924/workspaces/hashedin/Project3/venv/lib/python3.6/site-packages/django/contrib/auth/models.py", line 148, in _create_user
    raise ValueError('The given username must be set')
ValueError: The given username must be set
ERROR 2019-04-28 06:56:15,262 django.server "POST /api/v1/register/ HTTP/1.1" 500 18027
ERROR 2019-04-28 06:56:45,774 django.request Internal Server Error: /api/v1/register/
Traceback (most recent call last):
  File "/Users/300047924/workspaces/hashedin/Project3/venv/lib/python3.6/site-packages/django/core/handlers/exception.py", line 41, in inner
    response = get_response(request)
  File "/Users/300047924/workspaces/hashedin/Project3/venv/lib/python3.6/site-packages/django/core/handlers/base.py", line 187, in _get_response
    response = self.process_exception_by_middleware(e, request)
  File "/Users/300047924/workspaces/hashedin/Project3/venv/lib/python3.6/site-packages/django/core/handlers/base.py", line 185, in _get_response
    response = wrapped_callback(request, *callback_args, **callback_kwargs)
  File "/Users/300047924/workspaces/hashedin/Project3/venv/lib/python3.6/site-packages/django/views/decorators/csrf.py", line 58, in wrapped_view
    return view_func(*args, **kwargs)
  File "/Users/300047924/workspaces/hashedin/Project3/venv/lib/python3.6/site-packages/django/views/generic/base.py", line 68, in view
    return self.dispatch(request, *args, **kwargs)
  File "/Users/300047924/workspaces/hashedin/Project3/venv/lib/python3.6/site-packages/rest_framework/views.py", line 489, in dispatch
    response = self.handle_exception(exc)
  File "/Users/300047924/workspaces/hashedin/Project3/venv/lib/python3.6/site-packages/rest_framework/views.py", line 449, in handle_exception
    self.raise_uncaught_exception(exc)
  File "/Users/300047924/workspaces/hashedin/Project3/venv/lib/python3.6/site-packages/rest_framework/views.py", line 486, in dispatch
    response = handler(request, *args, **kwargs)
  File "/Users/300047924/workspaces/hashedin/Project3/foodordering/views.py", line 71, in post
    User.objects.create_user(serialized.data)
  File "/Users/300047924/workspaces/hashedin/Project3/venv/lib/python3.6/site-packages/django/contrib/auth/models.py", line 159, in create_user
    return self._create_user(username, email, password, **extra_fields)
  File "/Users/300047924/workspaces/hashedin/Project3/venv/lib/python3.6/site-packages/django/contrib/auth/models.py", line 148, in _create_user
    raise ValueError('The given username must be set')
ValueError: The given username must be set
ERROR 2019-04-28 06:56:45,792 django.server "POST /api/v1/register/ HTTP/1.1" 500 18028
ERROR 2019-04-28 06:57:05,290 django.request Internal Server Error: /api/v1/register/
Traceback (most recent call last):
  File "/Users/300047924/workspaces/hashedin/Project3/venv/lib/python3.6/site-packages/django/core/handlers/exception.py", line 41, in inner
    response = get_response(request)
  File "/Users/300047924/workspaces/hashedin/Project3/venv/lib/python3.6/site-packages/django/core/handlers/base.py", line 187, in _get_response
    response = self.process_exception_by_middleware(e, request)
  File "/Users/300047924/workspaces/hashedin/Project3/venv/lib/python3.6/site-packages/django/core/handlers/base.py", line 185, in _get_response
    response = wrapped_callback(request, *callback_args, **callback_kwargs)
  File "/Users/300047924/workspaces/hashedin/Project3/venv/lib/python3.6/site-packages/django/views/decorators/csrf.py", line 58, in wrapped_view
    return view_func(*args, **kwargs)
  File "/Users/300047924/workspaces/hashedin/Project3/venv/lib/python3.6/site-packages/django/views/generic/base.py", line 68, in view
    return self.dispatch(request, *args, **kwargs)
  File "/Users/300047924/workspaces/hashedin/Project3/venv/lib/python3.6/site-packages/rest_framework/views.py", line 489, in dispatch
    response = self.handle_exception(exc)
  File "/Users/300047924/workspaces/hashedin/Project3/venv/lib/python3.6/site-packages/rest_framework/views.py", line 449, in handle_exception
    self.raise_uncaught_exception(exc)
  File "/Users/300047924/workspaces/hashedin/Project3/venv/lib/python3.6/site-packages/rest_framework/views.py", line 486, in dispatch
    response = handler(request, *args, **kwargs)
  File "/Users/300047924/workspaces/hashedin/Project3/foodordering/views.py", line 71, in post
    User.objects.create_user(serialized.data)
  File "/Users/300047924/workspaces/hashedin/Project3/venv/lib/python3.6/site-packages/django/contrib/auth/models.py", line 159, in create_user
    return self._create_user(username, email, password, **extra_fields)
  File "/Users/300047924/workspaces/hashedin/Project3/venv/lib/python3.6/site-packages/django/contrib/auth/models.py", line 148, in _create_user
    raise ValueError('The given username must be set')
ValueError: The given username must be set
ERROR 2019-04-28 06:57:05,313 django.server "POST /api/v1/register/ HTTP/1.1" 500 18028
ERROR 2019-04-28 06:57:34,889 django.request Internal Server Error: /api/v1/register/
Traceback (most recent call last):
  File "/Users/300047924/workspaces/hashedin/Project3/venv/lib/python3.6/site-packages/django/core/handlers/exception.py", line 41, in inner
    response = get_response(request)
  File "/Users/300047924/workspaces/hashedin/Project3/venv/lib/python3.6/site-packages/django/core/handlers/base.py", line 187, in _get_response
    response = self.process_exception_by_middleware(e, request)
  File "/Users/300047924/workspaces/hashedin/Project3/venv/lib/python3.6/site-packages/django/core/handlers/base.py", line 185, in _get_response
    response = wrapped_callback(request, *callback_args, **callback_kwargs)
  File "/Users/300047924/workspaces/hashedin/Project3/venv/lib/python3.6/site-packages/django/views/decorators/csrf.py", line 58, in wrapped_view
    return view_func(*args, **kwargs)
  File "/Users/300047924/workspaces/hashedin/Project3/venv/lib/python3.6/site-packages/django/views/generic/base.py", line 68, in view
    return self.dispatch(request, *args, **kwargs)
  File "/Users/300047924/workspaces/hashedin/Project3/venv/lib/python3.6/site-packages/rest_framework/views.py", line 489, in dispatch
    response = self.handle_exception(exc)
  File "/Users/300047924/workspaces/hashedin/Project3/venv/lib/python3.6/site-packages/rest_framework/views.py", line 449, in handle_exception
    self.raise_uncaught_exception(exc)
  File "/Users/300047924/workspaces/hashedin/Project3/venv/lib/python3.6/site-packages/rest_framework/views.py", line 486, in dispatch
    response = handler(request, *args, **kwargs)
  File "/Users/300047924/workspaces/hashedin/Project3/foodordering/views.py", line 71, in post
    User.objects.create_user(serialized.data)
  File "/Users/300047924/workspaces/hashedin/Project3/venv/lib/python3.6/site-packages/django/contrib/auth/models.py", line 159, in create_user
    return self._create_user(username, email, password, **extra_fields)
  File "/Users/300047924/workspaces/hashedin/Project3/venv/lib/python3.6/site-packages/django/contrib/auth/models.py", line 148, in _create_user
    raise ValueError('The given username must be set')
ValueError: The given username must be set
ERROR 2019-04-28 06:57:34,907 django.server "POST /api/v1/register/ HTTP/1.1" 500 18028
ERROR 2019-04-28 06:58:47,151 django.request Internal Server Error: /api/v1/register/
Traceback (most recent call last):
  File "/Users/300047924/workspaces/hashedin/Project3/venv/lib/python3.6/site-packages/django/core/handlers/exception.py", line 41, in inner
    response = get_response(request)
  File "/Users/300047924/workspaces/hashedin/Project3/venv/lib/python3.6/site-packages/django/core/handlers/base.py", line 187, in _get_response
    response = self.process_exception_by_middleware(e, request)
  File "/Users/300047924/workspaces/hashedin/Project3/venv/lib/python3.6/site-packages/django/core/handlers/base.py", line 185, in _get_response
    response = wrapped_callback(request, *callback_args, **callback_kwargs)
  File "/Users/300047924/workspaces/hashedin/Project3/venv/lib/python3.6/site-packages/django/views/decorators/csrf.py", line 58, in wrapped_view
    return view_func(*args, **kwargs)
  File "/Users/300047924/workspaces/hashedin/Project3/venv/lib/python3.6/site-packages/django/views/generic/base.py", line 68, in view
    return self.dispatch(request, *args, **kwargs)
  File "/Users/300047924/workspaces/hashedin/Project3/venv/lib/python3.6/site-packages/rest_framework/views.py", line 489, in dispatch
    response = self.handle_exception(exc)
  File "/Users/300047924/workspaces/hashedin/Project3/venv/lib/python3.6/site-packages/rest_framework/views.py", line 449, in handle_exception
    self.raise_uncaught_exception(exc)
  File "/Users/300047924/workspaces/hashedin/Project3/venv/lib/python3.6/site-packages/rest_framework/views.py", line 486, in dispatch
    response = handler(request, *args, **kwargs)
  File "/Users/300047924/workspaces/hashedin/Project3/foodordering/views.py", line 69, in post
    if serialized.is_valid():
  File "/Users/300047924/workspaces/hashedin/Project3/venv/lib/python3.6/site-packages/rest_framework/serializers.py", line 231, in is_valid
    'Cannot call `.is_valid()` as no `data=` keyword argument was '
AssertionError: Cannot call `.is_valid()` as no `data=` keyword argument was passed when instantiating the serializer instance.
ERROR 2019-04-28 06:58:47,173 django.server "POST /api/v1/register/ HTTP/1.1" 500 17972
ERROR 2019-04-28 07:30:18,153 django.request Internal Server Error: /admin/foodordering/restaurant/1/change/
Traceback (most recent call last):
  File "/Users/300047924/workspaces/hashedin/Project3/venv/lib/python3.6/site-packages/django/contrib/admin/options.py", line 647, in get_form
    return modelform_factory(self.model, **defaults)
  File "/Users/300047924/workspaces/hashedin/Project3/venv/lib/python3.6/site-packages/django/forms/models.py", line 546, in modelform_factory
    return type(form)(class_name, (form,), form_class_attrs)
  File "/Users/300047924/workspaces/hashedin/Project3/venv/lib/python3.6/site-packages/django/forms/models.py", line 262, in __new__
    raise FieldError(message)
django.core.exceptions.FieldError: Unknown field(s) (descriptioncontact) specified for Restaurant

During handling of the above exception, another exception occurred:

Traceback (most recent call last):
  File "/Users/300047924/workspaces/hashedin/Project3/venv/lib/python3.6/site-packages/django/core/handlers/exception.py", line 41, in inner
    response = get_response(request)
  File "/Users/300047924/workspaces/hashedin/Project3/venv/lib/python3.6/site-packages/django/core/handlers/base.py", line 187, in _get_response
    response = self.process_exception_by_middleware(e, request)
  File "/Users/300047924/workspaces/hashedin/Project3/venv/lib/python3.6/site-packages/django/core/handlers/base.py", line 185, in _get_response
    response = wrapped_callback(request, *callback_args, **callback_kwargs)
  File "/Users/300047924/workspaces/hashedin/Project3/venv/lib/python3.6/site-packages/django/contrib/admin/options.py", line 551, in wrapper
    return self.admin_site.admin_view(view)(*args, **kwargs)
  File "/Users/300047924/workspaces/hashedin/Project3/venv/lib/python3.6/site-packages/django/utils/decorators.py", line 149, in _wrapped_view
    response = view_func(request, *args, **kwargs)
  File "/Users/300047924/workspaces/hashedin/Project3/venv/lib/python3.6/site-packages/django/views/decorators/cache.py", line 57, in _wrapped_view_func
    response = view_func(request, *args, **kwargs)
  File "/Users/300047924/workspaces/hashedin/Project3/venv/lib/python3.6/site-packages/django/contrib/admin/sites.py", line 224, in inner
    return view(request, *args, **kwargs)
  File "/Users/300047924/workspaces/hashedin/Project3/venv/lib/python3.6/site-packages/django/contrib/admin/options.py", line 1511, in change_view
    return self.changeform_view(request, object_id, form_url, extra_context)
  File "/Users/300047924/workspaces/hashedin/Project3/venv/lib/python3.6/site-packages/django/utils/decorators.py", line 67, in _wrapper
    return bound_func(*args, **kwargs)
  File "/Users/300047924/workspaces/hashedin/Project3/venv/lib/python3.6/site-packages/django/utils/decorators.py", line 149, in _wrapped_view
    response = view_func(request, *args, **kwargs)
  File "/Users/300047924/workspaces/hashedin/Project3/venv/lib/python3.6/site-packages/django/utils/decorators.py", line 63, in bound_func
    return func.__get__(self, type(self))(*args2, **kwargs2)
  File "/Users/300047924/workspaces/hashedin/Project3/venv/lib/python3.6/site-packages/django/contrib/admin/options.py", line 1408, in changeform_view
    return self._changeform_view(request, object_id, form_url, extra_context)
  File "/Users/300047924/workspaces/hashedin/Project3/venv/lib/python3.6/site-packages/django/contrib/admin/options.py", line 1437, in _changeform_view
    ModelForm = self.get_form(request, obj)
  File "/Users/300047924/workspaces/hashedin/Project3/venv/lib/python3.6/site-packages/django/contrib/admin/options.py", line 651, in get_form
    % (e, self.__class__.__name__)
django.core.exceptions.FieldError: Unknown field(s) (descriptioncontact) specified for Restaurant. Check fields/fieldsets/exclude attributes of class RestuarentAdmin.
ERROR 2019-04-28 07:30:18,243 django.server "GET /admin/foodordering/restaurant/1/change/ HTTP/1.1" 500 139275
